{
    "title" : "None of the specified endpoints were reachable",
    "uri" : "http://answers.coveo.com/questions/4696/none-of-the-specified-endpoints-were-reachable.html",
    "printableUri" : "https://answers.coveo.com/questions/4696/none-of-the-specified-endpoints-were-reachable.html",
    "clickUri" : "https://answers.coveo.com/questions/4696/none-of-the-specified-endpoints-were-reachable.html",
    "uniqueId" : "42.4247$http://answers.coveo.com/questions/4696/none-of-the-specified-endpoints-were-reachable.html",
    "excerpt" : "I have a 2nd sitecore instance on my local machine , on which I want to use coveo for sitecore. ... I get the above error when I try re-indexing from my 2nd sitecore instance. ... Re-indexing works...",
    "firstSentences" : null,
    "summary" : null,
    "flags" : "HasHtmlVersion",
    "hasHtmlVersion" : true,
    "hasMobileHtmlVersion" : false,
    "score" : 1030,
    "percentScore" : 72.21627,
    "rankingInfo" : null,
    "rating" : 3.0,
    "isTopResult" : false,
    "isRecommendation" : false,
    "titleHighlights" : [ ],
    "firstSentencesHighlights" : [ ],
    "excerptHighlights" : [ ],
    "printableUriHighlights" : [ ],
    "summaryHighlights" : [ ],
    "parentResult" : null,
    "childResults" : [ ],
    "totalNumberOfChildResults" : 0,
    "raw" : {
      "systitle" : "None of the specified endpoints were reachable",
      "sysauthor" : "psomtri",
      "sysurihash" : "p7tqOQJP25Tr1ðCF",
      "urihash" : "p7tqOQJP25Tr1ðCF",
      "numberofanswers" : 1,
      "sysuri" : "https://answers.coveo.com/questions/4696/none-of-the-specified-endpoints-were-reachable.html",
      "sysprintableuri" : "https://answers.coveo.com/questions/4696/none-of-the-specified-endpoints-were-reachable.html",
      "sitemappriority" : 0.1,
      "systransactionid" : 160351,
      "questionaskeddatestring" : "·\n            Apr 19, 2015 at 08:59 PM ·",
      "tags" : [ "coveoforsitecore", "multiple-instances" ],
      "sysconcepts" : "sitecore ; coveo ; looks ; config ; re-indexing ; data folder ; SitecorePassword elements ; datafolder ; encryption ; QueuePassword ; specified endpoints ; local machine ; connection",
      "concepts" : "sitecore ; coveo ; looks ; config ; re-indexing ; data folder ; SitecorePassword elements ; datafolder ; encryption ; QueuePassword ; specified endpoints ; local machine ; connection",
      "printableuri" : "https://answers.coveo.com/questions/4696/none-of-the-specified-endpoints-were-reachable.html",
      "documenttype" : "WebPage",
      "sysindexeddate" : 1517942083000,
      "permanentid" : "78ccd8fcfd405d73d58b22d2117ba0b2e17d91ee78faaf91465ded1f0990",
      "syslanguage" : [ "English" ],
      "transactionid" : 160351,
      "title" : "None of the specified endpoints were reachable",
      "date" : 1429488000000,
      "objecttype" : "Answers",
      "sitemapchangefrequency" : "Monthly",
      "answerauthor" : [ "Jean-François L'Heureux" ],
      "hasanswer" : "true",
      "audience" : [ "Administrator", "Developer" ],
      "commentauthor" : [ "psomtri" ],
      "hasacceptedanswer" : "true",
      "sourcetype" : "Sitemap",
      "sysconnectortype" : "SitemapCrawler",
      "rowid" : 5447530,
      "numberofcomments" : 1,
      "size" : 72578,
      "sysdocumenttype" : "WebPage",
      "questionvotes" : 0,
      "clickableuri" : "https://answers.coveo.com/questions/4696/none-of-the-specified-endpoints-were-reachable.html",
      "syssource" : "AnswersCloud",
      "orderingid" : 212384744911577829,
      "acceptedanswers" : 1,
      "syssize" : 72578,
      "sysdate" : 1429488000000,
      "author" : "psomtri",
      "source" : "AnswersCloud",
      "questionbodyhtml" : "<div class=\"question-body\">\n                <p>I have a 2nd sitecore instance on my local machine , on which I want to use coveo for sitecore. I get the above error when I try re-indexing from my 2nd sitecore instance. Re-indexing works fine on my 1st sitecore instance. I have verified config files every thing looks same as 1st sitecore instance. In the coveo diagnostic page on 2nd instance sitecore control panel I see the above error as well. What am I missing?</p>\n                </div>",
      "sitemaplastmodified" : 1429488000000,
      "collection" : "default",
      "syssourcetype" : "Sitemap",
      "indexeddate" : 1517942083000,
      "questionnumber" : 4696,
      "connectortype" : "SitemapCrawler",
      "filetype" : "html",
      "sysclickableuri" : "https://answers.coveo.com/questions/4696/none-of-the-specified-endpoints-were-reachable.html",
      "sysfiletype" : "html",
      "language" : [ "English" ],
      "sitemapparenturl" : "http://answers.coveo.com/questions/1.xml",
      "questionauthor" : "psomtri",
      "sitename" : "Answers",
      "sysrowid" : 5447530,
      "uri" : "https://answers.coveo.com/questions/4696/none-of-the-specified-endpoints-were-reachable.html",
      "syscollection" : "default",
      "sitelanguage" : [ "English" ]
    },
    "Title" : "None of the specified endpoints were reachable",
    "Uri" : "http://answers.coveo.com/questions/4696/none-of-the-specified-endpoints-were-reachable.html",
    "PrintableUri" : "https://answers.coveo.com/questions/4696/none-of-the-specified-endpoints-were-reachable.html",
    "ClickUri" : "https://answers.coveo.com/questions/4696/none-of-the-specified-endpoints-were-reachable.html",
    "UniqueId" : "42.4247$http://answers.coveo.com/questions/4696/none-of-the-specified-endpoints-were-reachable.html",
    "Excerpt" : "I have a 2nd sitecore instance on my local machine , on which I want to use coveo for sitecore. ... I get the above error when I try re-indexing from my 2nd sitecore instance. ... Re-indexing works...",
    "FirstSentences" : null
  }